wandb: Network error resolved after 0:00:32.683575, resuming normal operation.
Traceback (most recent call last):
  File "./run.py", line 12, in <module>
    main()
  File "./run.py", line 8, in main
    trainer =  Train(args)
  File "/home/eiden/eiden/satellite/train/train.py", line 236, in __init__
    self.model = get_pretrained_model('monai_swinunet').get()
  File "/home/eiden/eiden/satellite/train/../network/models.py", line 25, in get
    model = self.monai_swinunet()
  File "/home/eiden/eiden/satellite/train/../network/models.py", line 56, in monai_swinunet
    from monai.networks.nets import swin_unetr
ModuleNotFoundError: No module named 'monai'